Workbook
Name Slicer_Product_Category: #N/A
Name Slicer_Region: #N/A
Name Slicer_Salesperson: #N/A

Sheet Raw_Data
A1: Order ID | B1: Order Date | C1: Region | D1: City | E1: Product Category | F1: Product | G1: Salesperson | H1: Units Sold | I1: Unit Price | J1: Discount | K1: Revenue | L1: Cost | M1: Profit | N1: Payment Method
A2: ORD-2025-0001 | B2: 45937 | C2: Central | D2: Lahore | E2: Electronics | F2: Headphones | G2: Sara Ahmed | H2: 4 | I2: 13857.85 | J2: 0.15 | K2: 47116.69 | L2: 32051.33 | M2: 15065.36 | N2: Digital Wallet
A3: ORD-2025-0002 | B3: 45990 | C3: North | D3: Islamabad | E3: Electronics | F3: Smartphone | G3: Bilal Hussain | H3: 4 | I3: 92078.83 | J3: 0 | K3: 368315.32 | L3: 274526.11 | M3: 93789.21 | N3: Credit Card
A4: ORD-2025-0003 | B4: 45768 | C4: South | D4: Quetta | E4: Home Appliances | F4: Air Conditioner | G4: Fatima Raza | H4: 3 | I4: 139279.81 | J4: 0.05 | K4: 396947.46 | L4: 299803.65 | M4: 97143.81 | N4: Cash
A5: ORD-2025-0004 | B5: 45932 | C5: North | D5: Rawalpindi | E5: Electronics | F5: Headphones | G5: Sara Ahmed | H5: 6 | I5: 14740.64 | J5: 0 | K5: 88443.84 | L5: 50237.2 | M5: 38206.64 | N5: Digital Wallet
A6: ORD-2025-0005 | B6: 45806 | C6: North | D6: Peshawar | E6: Home Appliances | F6: Vacuum Cleaner | G6: Sara Ahmed | H6: 4 | I6: 27883.75 | J6: 0 | K6: 111535 | L6: 73172.77 | M6: 38362.23 | N6: Credit Card
A7: ORD-2025-0006 | B7: 45794 | C7: North | D7: Rawalpindi | E7: Home Appliances | F7: Water Dispenser | G7: Sara Ahmed | H7: 6 | I7: 23177.6 | J7: 0.05 | K7: 132112.32 | L7: 93346.29 | M7: 38766.03 | N7: CREDIT CARD
A8: ORD-2025-0007 | B8: 45770 | C8: Central | D8: Multan | E8: Office Supplies | F8: Office Chair | G8: Fatima Raza | H8: 8 | I8: 27950.32 | J8: 0.15 | K8: 190062.18 | L8: 154762.04 | M8: 35300.14 | N8: Cash
A9: ORD-2025-0008 | B9: 45819 | C9: North | D9: Islamabad | E9: Home Appliances | F9: Water Dispenser | G9: Ayesha Noor | H9: 5 | I9: 22799.46 | J9: 0.1 | K9: 102597.57 | L9: 81476.31 | M9: 21121.26 | N9: Digital Wallet
A10: ORD-2025-0009 | B10: 45792 | C10: South | D10: Quetta | E10: Accessories | F10: USB Hub | G10: Bilal Hussain | H10: 5 | I10: 3957.83 | J10: 0.15 | K10: 16820.78 | L10: 10597.61 | M10: 6223.17 | N10: Digital Wallet
A11: ORD-2025-0010 | B11: 45739 | C11: South | D11: Karachi | E11: Office Supplies | F11: Keyboard | G11: Bilal Hussain | H11: 2 | I11: 8847.86 | J11: 0 | K11: 17695.72 | L11: 9610.85 | M11: 8084.87 | N11: Cash
A12: ORD-2025-0011 | B12: 02/10/2025 | C12: South | D12: Hyderabad | E12: Accessories | F12: Webcam | G12: Hamza Shah | H12: 1 | I12: 11831.72 | J12: 0 | K12: 11831.72 | L12: 6615.18 | M12: 5216.54 | N12: Bank Transfer
A13: ORD-2025-0012 | B13: 45792 | C13: North | D13: Rawalpindi | E13: Accessories | F13: USB Hub | G13: Usman Malik | H13: 8 | I13: 3866.18 | J13: 0.15 | K13: 26290.02 | L13: 17326 | M13: 8964.02 | N13: Cash
A14: ORD-2025-0013 | B14: 45929 | C14: Central | D14: Faisalabad | E14: Office Supplies | F14: Office Chair | G14: Ali Khan | H14: 6 | I14: 29697.05 | J14: 0.1 | K14: 160364.07 | L14: 118188.93 | M14: 42175.14 | N14: Bank Transfer
A15: ORD-2025-0014 | B15: 45698 | C15: South | D15: Karachi | E15: Electronics | F15: Headphones | G15: Sara Ahmed | H15: 5 | I15: 13895.53 | J15: 0 | K15: 69477.65 | L15: 42289.89 | M15: 27187.76 | N15: Digital Wallet
A16: ORD-2025-0015 | B16: 45968 | C16: North | D16: Peshawar | E16: Office Supplies | F16: Office Chair | G16: Bilal Hussain | H16: 8 | I16: 30537.63 | J16: 0 | K16: 244301.04 | L16: 150260.2 | M16: 94040.84 | N16: Credit Card
A17: ORD-2025-0016 | B17: 45922 | C17: central | D17: Multan | E17: Office Supplies | F17: Desk | G17: Zara Iqbal | H17: 7 | I17: 41010.51 | J17: 0.15 | K17: 244012.53 | L17: 181297.38 | M17: 62715.15 | N17: Cash
A18: ORD-2025-0017 | B18: 45661 | C18: North | D18: Islamabad | E18: Electronics | F18: Headphones | G18: Sara Ahmed | H18: 1 | I18: 14704.88 | J18: 0 | K18: 14704.88 | L18: 8291.76 | M18: 6413.12 | N18: Cash
A19: ORD-2025-0018 | B19: 45767 | C19: North | D19: Islamabad | E19: Electronics | F19: Headphones | G19: Usman Malik | H19: 2 | I19: 14532.84 | J19: 0.05 | K19: 27612.4 | L19: 16675.99 | M19: 10936.41 | N19: Digital Wallet
A20: ORD-2025-0019 | B20: 45868 | C20: North | D20: Rawalpindi | E20: Accessories | F20: USB Hub | G20: Zara Iqbal | H20: 2 | I20: 3929.14 | J20: 0.05 | K20: 7465.37 | L20: 4178.16 | M20: 3287.21 | N20: Cash
A21: ORD-2025-0020 | B21: 45755 | C21: Central | D21: Multan | E21: Electronics | F21: Laptop | G21: Zara Iqbal | H21: 7 | I21: 191755.12 | J21: 0 | K21: 1342285.8 | L21: 981481.51 | M21: 360804.33 | N21: Credit Card
A22: ORD-2025-0021 | B22: 45939 | C22: South | D22: Karachi | E22: Home Appliances | F22: Water Dispenser | G22: Sara Ahmed | H22: 4 | I22: 25967.98 | J22: 0 | K22: 103871.92 | L22: 63264.41 | M22: 40607.51 | N22: Cash
A23: ORD-2025-0022 | B23: 45863 | C23: Central | D23: Multan | E23: Electronics | F23: Laptop | G23: Ali Khan | H23: 4 | I23: 175122.81 | J23: 0.05 | K23: 665466.68 | L23: 570098.81 | M23: 95367.87 | N23: Credit Card
A24: ORD-2025-0023 | B24: 45942 | C24: South | D24: Karachi | E24: Accessories | F24: Webcam | G24: Zara Iqbal | H24: 8 | I24: 11104.86 | J24: 0.15 | K24: 75513.05 | L24: 53924.64 | M24: 21588.41 | N24: Credit Card
... A35: ORD-2025-0034 | B35: 45779 | C35: Central | D35: Lahore | E35: Electronics | F35: Headphones | G35: Usman Malik | H35: 7 | I35: 15599.3 | J35: 0.15 | K35: 92815.83 | L35: 56299 | M35: 36516.83 | N35: Credit Card
A36: ORD-2025-0035 | B36: 45794 | C36: South | D36: Karachi | E36: Office Supplies | F36: Desk | G36: Usman Malik | H36: 7 | I36: 39837.59 | J36: 0.15 | K36: 237033.66 | L36: 186868.95 | M36: 50164.71
A37: ORD-2025-0036 | B37: 45774 | C37: South | D37: Karachi | E37: Accessories | F37: USB Hub | G37: Ayesha Noor | H37: 4 | I37: 4412.75 | J37: 0.05 | K37: 16768.45 | L37: 8353.6 | M37: 8414.85 | N37: Cash
A38: ORD-2025-0037 | B38: 45918 | C38: Central | D38: Lahore | E38: Accessories | F38: Webcam | G38: Bilal Hussain | H38: 5 | I38: 12170.41 | J38: 0.05 | K38: 57809.45 | L38: 32323.86 | M38: 25485.59 | N38: Bank Transfer
A39: ORD-2025-0038 | B39: 45818 | C39: North | D39: Islamabad | E39: Home Appliances | F39: Microwave | G39: Bilal Hussain | H39: 5 | I39: 30562 | J39: 0.1 | K39: 137529 | L39: 112547.19 | M39: 24981.81 | N39: Cash
A40: ORD-2025-0039 | B40: 45933 | C40: South | D40: Quetta | E40: Office Supplies | F40: Desk | G40: Ayesha Noor | H40: 1 | I40: 39269.41 | J40: 0 | K40: 39269.41 | L40: 26166.26 | M40: 13103.15 | N40: Bank Transfer
A41: ORD-2025-0040 | B41: 45999 | C41: South | D41: Karachi | E41: Home Appliances | F41: Vacuum Cleaner | G41: Bilal Hussain | H41: 2 | I41: 27949.34 | J41: 0.05 | K41: 53103.75 | L41: 36197.95 | M41: 16905.8 | N41: Bank Transfer
A42: ORD-2025-0041 | B42: 45747 | C42: South | D42: Quetta | E42: Home Appliances | F42: Microwave | G42: Hamza Shah | H42: 4 | I42: 32579.96 | J42: 0.05 | K42: 123803.85 | L42: 91567.1 | M42: 32236.75 | N42: Digital Wallet
A43: ORD-2025-0042 | B43: 45822 | C43: Central | D43: Lahore | E43: Home Appliances | F43: Vacuum Cleaner | G43: Zara Iqbal | H43: 4 | I43: 26697.12 | J43: 0.1 | K43: 96109.63 | L43: 72897.57 | M43: 23212.06 | N43: Digital Wallet
A44: ORD-2025-0043 | B44: 45982 | C44: South | D44: Quetta | E44: Office Supplies | F44: Keyboard | G44: Fatima Raza | I44: 8716.04 | J44: 0.05 | K44: 24840.71 | L44: 14789.4 | M44: 10051.31 | N44: Cash
A45: ORD-2025-0044 | B45: 45901 | C45: North | D45: Peshawar | E45: Home Appliances | F45: Microwave | G45: Sara Ahmed | H45: 4 | I45: 31138.03 | J45: 0 | K45: 124552.12 | L45: 88842.51 | M45: 35709.61 | N45: Digital Wallet
A46: ORD-2025-0045 | B46: 45660 | C46: South | D46: Quetta | E46: Office Supplies | F46: Keyboard | G46: Sara Ahmed | H46: 8 | I46: 8363.53 | J46: 0 | K46: 66908.24 | L46: 39824.22 | M46: 27084.02 | N46: Digital Wallet
A47: ORD-2025-0046 | B47: 45895 | C47: North | D47: Islamabad | E47: Accessories | F47: Power Bank | G47: Fatima Raza | H47: 4 | I47: 6934.17 | J47: 0 | K47: 27736.68 | L47: 14428.11 | M47: 13308.57 | N47: Digital Wallet
A48: ORD-2025-0047 | B48: 45784 | C48: Central | D48: Multan | E48: Accessories | F48: Mouse | G48: Hamza Shah | H48: 3 | I48: 5402.72 | J48: 0.05 | K48: 15397.75 | L48: 8112.19 | M48: 7285.56 | N48: Digital Wallet
A49: ORD-2025-0048 | B49: 45821 | C49: Central | D49: Lahore | E49: Home Appliances | F49: Water Dispenser | G49: Sara Ahmed | H49: 2 | I49: 25337.1 | J49: 0 | K49: 50674.2 | L49: 31253.03 | M49: 19421.17 | N49: Credit Card
A50: ORD-2025-0049 | B50: 45896 | C50: North | D50: Islamabad | E50: Accessories | F50: USB Hub | G50: Bilal Hussain | H50: 4 | I50: 3907.16 | J50: 0.05 | K50: 14847.21 | L50: 8342.56 | M50: 6504.65 | N50: Cash
...

Sheet Clean Data
A1: Order ID | B1: Order Date | C1: Region | D1: City | E1: Product Category | F1: Product | G1: Salesperson | H1: Units Sold | I1: Unit Price | J1: Discount | K1: Revenue | L1: Cost | M1: Profit | N1: Payment Method | O1: Profit Margin
A2: ORD-2025-0001 | B2: 45937 | C2: Central | D2: Lahore | E2: Electronics | F2: Headphones | G2: Sara Ahmed | H2: 4 | I2: 13857.85 | J2: 0.15 | K2: 47116.69 | L2: 32051.33 | M2: 15065.36 | N2: Digital Wallet | O2: =IFERROR(RawSalesTable_[[#This Row],[Profit]]/RawSalesTable_[[#This Row],[Revenue]],0) -> 0.31974572
A3: ORD-2025-0002 | B3: 45990 | C3: North | D3: Islamabad | E3: Electronics | F3: Smartphone | G3: Bilal Hussain | H3: 4 | I3: 92078.83 | J3: 0 | K3: 368315.32 | L3: 274526.11 | M3: 93789.21 | N3: Credit Card | O3: =IFERROR(RawSalesTable_[[#This Row],[Profit]]/RawSalesTable_[[#This Row],[Revenue]],0) -> 0.25464379
A4: ORD-2025-0003 | B4: 45768 | C4: South | D4: Quetta | E4: Home Appliances | F4: Air Conditioner | G4: Fatima Raza | H4: 3 | I4: 139279.81 | J4: 0.05 | K4: 396947.46 | L4: 299803.65 | M4: 97143.81 | N4: Cash | O4: =IFERROR(RawSalesTable_[[#This Row],[Profit]]/RawSalesTable_[[#This Row],[Revenue]],0) -> 0.24472712
A5: ORD-2025-0004 | B5: 45932 | C5: North | D5: Rawalpindi | E5: Electronics | F5: Headphones | G5: Sara Ahmed | H5: 6 | I5: 14740.64 | J5: 0 | K5: 88443.84 | L5: 50237.2 | M5: 38206.64 | N5: Digital Wallet | O5: =IFERROR(RawSalesTable_[[#This Row],[Profit]]/RawSalesTable_[[#This Row],[Revenue]],0) -> 0.43198758
A6: ORD-2025-0005 | B6: 45806 | C6: North | D6: Peshawar | E6: Home Appliances | F6: Vacuum Cleaner | G6: Sara Ahmed | H6: 4 | I6: 27883.75 | J6: 0 | K6: 111535 | L6: 73172.77 | M6: 38362.23 | N6: Credit Card | O6: =IFERROR(RawSalesTable_[[#This Row],[Profit]]/RawSalesTable_[[#This Row],[Revenue]],0) -> 0.34394791
A7: ORD-2025-0006 | B7: 45794 | C7: North | D7: Rawalpindi | E7: Home Appliances | F7: Water Dispenser | G7: Sara Ahmed | H7: 6 | I7: 23177.6 | J7: 0.05 | K7: 132112.32 | L7: 93346.29 | M7: 38766.03 | N7: Credit Card | O7: =IFERROR(RawSalesTable_[[#This Row],[Profit]]/RawSalesTable_[[#This Row],[Revenue]],0) -> 0.29343236
A8: ORD-2025-0007 | B8: 45770 | C8: Central | D8: Multan | E8: Office Supplies | F8: Office Chair | G8: Fatima Raza | H8: 8 | I8: 27950.32 | J8: 0.15 | K8: 190062.18 | L8: 154762.04 | M8: 35300.14 | N8: Cash | O8: =IFERROR(RawSalesTable_[[#This Row],[Profit]]/RawSalesTable_[[#This Row],[Revenue]],0) -> 0.18572943
A9: ORD-2025-0008 | B9: 45819 | C9: North | D9: Islamabad | E9: Home Appliances | F9: Water Dispenser | G9: Ayesha Noor | H9: 5 | I9: 22799.46 | J9: 0.1 | K9: 102597.57 | L9: 81476.31 | M9: 21121.26 | N9: Digital Wallet | O9: =IFERROR(RawSalesTable_[[#This Row],[Profit]]/RawSalesTable_[[#This Row],[Revenue]],0) -> 0.20586511
A10: ORD-2025-0009 | B10: 45792 | C10: South | D10: Quetta | E10: Accessories | F10: Usb Hub | G10: Bilal Hussain | H10: 5 | I10: 3957.83 | J10: 0.15 | K10: 16820.78 | L10: 10597.61 | M10: 6223.17 | N10: Digital Wallet | O10: =IFERROR(RawSalesTable_[[#This Row],[Profit]]/RawSalesTable_[[#This Row],[Revenue]],0) -> 0.36996917
A11: ORD-2025-0010 | B11: 45739 | C11: South | D11: Karachi | E11: Office Supplies | F11: Keyboard | G11: Bilal Hussain | H11: 2 | I11: 8847.86 | J11: 0 | K11: 17695.72 | L11: 9610.85 | M11: 8084.87 | N11: Cash | O11: =IFERROR(RawSalesTable_[[#This Row],[Profit]]/RawSalesTable_[[#This Row],[Revenue]],0) -> 0.45688279
A12: ORD-2025-0011 | B12: 45698 | C12: South | D12: Hyderabad | E12: Accessories | F12: Webcam | G12: Hamza Shah | H12: 1 | I12: 11831.72 | J12: 0 | K12: 11831.72 | L12: 6615.18 | M12: 5216.54 | N12: Bank Transfer | O12: =IFERROR(RawSalesTable_[[#This Row],[Profit]]/RawSalesTable_[[#This Row],[Revenue]],0) -> 0.44089448
A13: ORD-2025-0012 | B13: 45792 | C13: North | D13: Rawalpindi | E13: Accessories | F13: Usb Hub | G13: Usman Malik | H13: 8 | I13: 3866.18 | J13: 0.15 | K13: 26290.02 | L13: 17326 | M13: 8964.02 | N13: Cash | O13: =IFERROR(RawSalesTable_[[#This Row],[Profit]]/RawSalesTable_[[#This Row],[Revenue]],0) -> 0.34096665
... A1437: ORD-2025-1480 | B1437: 45681 | C1437: Central | D1437: Lahore | E1437: Electronics | F1437: Smartphone | G1437: Sara Ahmed | H1437: 3 | I1437: 95106.92 | J1437: 0.5 | K1437: 285320.76 | L1437: 212133.51 | M1437: 73187.25 | N1437: Digital Wallet | O1437: =IFERROR(RawSalesTable_[[#This Row],[Profit]]/RawSalesTable_[[#This Row],[Revenue]],0) -> 0.25650867

Sheet Analysis
E4: KPI | F4: Value
E6: Total Revenue | F6: =SUM(RawSalesTable_[Revenue]) -> 2.5552816e+08
E7: Total profit | F7: =SUM(RawSalesTable_[Profit]) -> 62309485
E8: Overall profit margin | F8: =F7/F6 -> 0.24384587
E9: Total Transactions | F9: =COUNTA(RawSalesTable_[Order ID]) -> 1436
E10: Total units sold | F10: =SUM(RawSalesTable_[Units Sold]) -> 6373

Sheet Pivot_Analysis
A4: Row Labels | B4: REVENUE | C4: PROFIT
A5: Central | B5: 79493158 | C5: 19434954
A6: North | B6: 93709201 | C6: 22791766
A7: South | B7: 82325796 | C7: 20082765
A8: Grand Total | B8: 2.5552816e+08 | C8: 62309485
A17: Row Labels | B17: Sum of Revenue
A18: Air Conditioner | B18: 46049744
A19: Laptop | B19: 58810127
A20: Microwave | B20: 13453895
A21: Monitor | B21: 17659357
A22: Smartphone | B22: 41872833
A23: Grand Total | B23: 1.7784596e+08
A31: Row Labels | B31: Sum of Revenue
A32: Ali Khan | B32: 31564555
A33: Ayesha Noor | B33: 24502798
A34: Bilal Hussain | B34: 39684213
A35: Fatima Raza | B35: 33899568
A36: Hamza Shah | B36: 31826740
A37: Sara Ahmed | B37: 32684982
A38: Usman Malik | B38: 28693708
A39: Zara Iqbal | B39: 32671591
A40: Grand Total | B40: 2.5552816e+08
A48: Row Labels | B48: Sum of Revenue
A49: Accessories | B49: 10243524
A50: Electronics | B50: 1.2373161e+08
A51: Home Appliances | B51: 82090558
A52: Office Supplies | B52: 39462463
A53: Grand Total | B53: 2.5552816e+08

Sheet DashBoard
A1: RETAIL SALES PERFORMANCE DASHBOARD
B4: TOTAL REVENUE | E4: TOTAL PROFIT | H4: PROFIT MARGIN | K4: TRANSACTIONS | N4: UNITS SOLD
B5: =Analysis!F6 -> 2.5552816e+08 | E5: =Analysis!F7 -> 62309485 | H5: =Analysis!F8 -> 0.24384587 | K5: =Analysis!F9 -> 1436 | N5: =Analysis!F10 -> 6373
